Workbook

Sheet Categories
A1: Sources by category: OpenAI–Hugging Face (CAS-2026-0001)
A2: Counts after deduplication, as of 19 Oct 2026. Round 1 and Now are counts from the merged review list; Added is calculated.
A4: Category | B4: Round 1 | C4: Added in round 2 | D4: Now
A5: Expert newsletters and commentary | B5: 65 | C5: =D5-B5 -> 39 | D5: 104
A6: Think-tank analysis | B6: 9 | C6: =D6-B6 -> 6 | D6: 15
A7: Podcasts and video | B7: 6 | C7: =D7-B7 -> 9 | D7: 15
A8: News articles | B8: 87 | C8: =D8-B8 -> 3 | D8: 90
A9: Official and legal documents | B9: 54 | C9: =D9-B9 -> 3 | D9: 57
A10: Technical reports and papers | B10: 39 | C10: =D10-B10 -> 4 | D10: 43
A11: Company disclosures | B11: 25 | C11: =D11-B11 -> 1 | D11: 26
A12: Datasets and trackers | B12: 11 | C12: =D12-B12 -> 0 | D12: 11
A13: Total | B13: =SUM(B5:B12) -> 296 | C13: =SUM(C5:C12) -> 65 | D13: =SUM(D5:D12) -> 361
A15: Blue figures are counts taken from the merged review list (research/pilot-openai-hf). Black figures are formulas.

Sheet Coverage summary
A1: Coverage summary
A2: Calculated from the Coverage sheet.
A4: Group | B4: Names checked | C4: Published on incident | D4: Share published
A5: Leading organisations and education | B5: =COUNTIF(Coverage!$A$5:$A$145,A5) -> 48 | C5: =COUNTIFS(Coverage!$A$5:$A$145,A5,Coverage!$D$5:$D$145,"Yes") -> 15 | D5: =IF(B5=0,0,C5/B5) -> 0.3125
A6: Expert newsletters | B6: =COUNTIF(Coverage!$A$5:$A$145,A6) -> 38 | C6: =COUNTIFS(Coverage!$A$5:$A$145,A6,Coverage!$D$5:$D$145,"Yes") -> 28 | D6: =IF(B6=0,0,C6/B6) -> 0.73684211
A7: Think tanks | B7: =COUNTIF(Coverage!$A$5:$A$145,A7) -> 55 | C7: =COUNTIFS(Coverage!$A$5:$A$145,A7,Coverage!$D$5:$D$145,"Yes") -> 14 | D7: =IF(B7=0,0,C7/B7) -> 0.25454545
A8: Total | B8: =SUM(B5:B7) -> 141 | C8: =SUM(C5:C7) -> 57 | D8: =IF(B8=0,0,C8/B8) -> 0.40425532

Sheet Coverage
A1: What we checked: writers, think tanks and organisations
A2: One row per name searched in round 2. "Published on incident" = Yes if the researcher found and opened something on this incident.
A4: Group | B4: Name | C4: Outlet | D4: Published on incident | E4: Links found | F4: Researcher note
A5: Leading organisations and education | B5: BlueDot Impact | D5: Yes | E5: https://bluedot.org/courses/ai-governance/1/3 https://bluedot.org/courses/agi-strategy/1/4 | F5: Two dedicated course lessons, in Frontier AI Governance (U1.3) and AGI Strategy (U1.4). No blog post about the incident; the 12 Sep 'What we're building' post mentions only 'rogue AI swarms' in general terms. No lesson title or reading in Technical AI Safety mentions the incident (lessons 3/4 and 5/1 checked), and none in the Future of AI or Biosecurity course pages.
A6: Leading organisations and education | B6: AISafety.com | D6: No | F6: Nothing found from AISafety.com itself. Searches surfaced only third-party discussion-group listings (e.g. luma.com SAIN Amsterdam), which were not opened.
A7: Leading organisations and education | B7: AI Safety Info (Stampy) | D7: No | F7: One search; no aisafety.info page surfaced.
A8: Leading organisations and education | B8: 80,000 Hours | D8: Yes | E8: https://80000hours.org/podcast/episodes/hugging-face-hack/ https://www.youtube.com/watch?v=xOi5nDH0lu0 https://80000hours.substack.com/p/the-future-of-ai-crime https://80000hours.org/problem-profiles/loss-of-control/ | F8: Podcast/video explainer, a newsletter article and an updated problem profile. The site banner links an incident hub page, which was not located. The May METR rogue-deployments episode predates the incident.
A9: Leading organisations and education | B9: MATS | D9: No | F9: Combined search with ERA/LASR; nothing found.
A10: Leading organisations and education | B10: ERA Cambridge | D10: No | F10: Nothing found.
A11: Leading organisations and education | B11: LASR Labs | D11: No | F11: Nothing found.
A12: Leading organisations and education | B12: Constellation | D12: No | F12: Nothing found.
A13: Leading organisations and education | B13: Apart Research | D13: No | E13: https://apartresearch.com/sprints/projects/one-incident-four-regimes-an-evidencesufficient-request-for-information-a-filed-critical-safety-incident-report-and-two-fixes-to-the-ai-kill-switch-act-dm64 | F13: Only the sprint project already in ALREADY_HAVE. No new Apart items found.
A14: Leading organisations and education | B14: Cooperative AI Foundation | D14: Yes | E14: https://www.cooperativeai.com/post/lessons-from-multi-agent-safety-incidents | F14: Dedicated incident-lessons post (26 Aug). Its 2 Sep IASEAI multi-agent governance memo does not mention the incident. The LessWrong multi-agent post (already have) is by an individual with no stated CAIF affiliation.
A15: Leading organisations and education | B15: EA Forum / LessWrong (organisational posts) | D15: Yes | E15: https://forum.effectivealtruism.org/posts/aPsKjouh9YhTMBqtM/the-hugging-face-attack-surprised-me | F15: Only items already in ALREADY_HAVE (Cotra crosspost, multi-agent post). The CAIS AI Safety Newsletter sequence on LessWrong shows no 2026 issues; the AISN issues 78-80 are already held.
A16: Leading organisations and education | B16: METR | D16: Yes | E16: https://metr.org/blog/2026-09-30-chris-painter-senate-testimony/ | F16: New: METR's copy of the Painter testimony. Investigation report, 28 Jul post and agent-incidents page already held. The agent-incidents page was last updated 19 May 2026 and does not list the HF incident.
A17: Leading organisations and education | B17: Redwood Research | D17: Yes | F17: Only items already held (research page, blog post, brief investigation). Nothing further found.
A18: Leading organisations and education | B18: Apollo Research | D18: Yes | E18: https://apolloresearch.ai/blog/embedded-evaluators-are-necessary-for-meaningful-external-testing https://apolloresearch.ai/blog/on-testifying-on-misaligned-ai-in-the-us-senate | F18: Two new blog posts (29-30 Sep). Apollo also ran evaluations cited in the GPT-6 Astra system card.
A19: Leading organisations and education | B19: Palisade Research | D19: Yes | E19: https://swarmtraces.org/ | F19: Jeffrey Ladish (Palisade) is a co-author of swarmtraces.org, which is already held. No Palisade-branded post was found.
A20: Leading organisations and education | B20: FAR.AI | D20: No | F20: Nothing found.
A21: Leading organisations and education | B21: Epoch AI | D21: No | F21: Nothing found.
A22: Leading organisations and education | B22: AI Futures Project | D22: Yes | F22: Kokotajlo's HSGAC testimony is already held. The blog index (blog.aifutures.org) did not render, so whether it has posts on the incident is unverified.
A23: Leading organisations and education | B23: AI Lab Watch | D23: No | F23: Nothing found.
A24: Leading organisations and education | B24: MIRI | D24: No | F24: Nothing found.
A25: Leading organisations and education | B25: Conjecture | D25: No | F25: Not searched separately (search budget exhausted).
A26: Leading organisations and education | B26: ControlAI | D26: No | F26: Combined search with PauseAI; nothing from either organisation.
A27: Leading organisations and education | B27: PauseAI | D27: No | F27: Nothing incident-specific found. The protest coverage that turned up (Decrypt, Mar 2026) predates the incident.
A28: Leading organisations and education | B28: Center for AI Safety | D28: Yes | F28: AISN issues 78-80 are already held. No separate CAIS statement found. Later AISN issues could not be checked because the search budget ran out.
A29: Leading organisations and education | B29: Future of Life Institute | D29: No | F29: Nothing found. A 14 Oct open letter on AI and cybersecurity (406 signatories) was reported by YourStory, but its organiser and URL were not identified.
A30: Leading organisations and education | B30: The Midas Project | D30: No | F30: Nothing found. Preparedness Framework rewrite coverage (Axios, already held) was the only result.
A31: Leading organisations and education | B31: Secure AI Project | D31: No | F31: Nothing found.
A32: Leading organisations and education | B32: Anthropic | D32: Yes | E32: https://www.anthropic.com/news/investigating-incidents-cybersecurity-evals | F32: Nothing beyond what is already held. The CAIF post cites an Anthropic August 2026 Risk Report PDF that was not opened.
A33: Leading organisations and education | B33: Google DeepMind | D33: No | F33: No statement found.
A34: Leading organisations and education | B34: Meta | D34: No | F34: No statement about the HF incident. Search snippets point to a separate Meta containment incident, which was not opened.
A35: Leading organisations and education | B35: xAI | D35: No | F35: Nothing found.
A36: Leading organisations and education | B36: Microsoft | D36: No | F36: Nothing found.
A37: Leading organisations and education | B37: Mistral | D37: No | F37: Nothing found.
A38: Leading organisations and education | B38: Hugging Face | D38: Yes | E38: https://www.csis.org/events/ai-agent-containment-failures-technical-realities-and-policy-responses | F38: No new HF blog posts found. HF's Ian Reynolds gave a technical briefing at the 24 Aug CSIS/LawAI event.
A39: Leading organisations and education | B39: OpenAI | D39: Yes | E39: https://deploymentsafety.openai.com/gpt-6-astra | F39: New: the GPT-6 Astra system card (3 Sep), which covers post-incident containment and Preparedness changes. The misalignment-reporting framework and Preparedness update are already held. The 5 Sep wiki statement could not be searched because the budget ran out.
A40: Leading organisations and education | B40: Frontier Model Forum | D40: No | F40: Nothing found.
A41: Leading organisations and education | B41: Partnership on AI | D41: No | F41: Nothing found.
...

Sheet Follow-ups
A1: Follow-ups
A2: Sources that could not be opened and checks cut short by the search limit. Status column is for you to fill in.
A4: Item | B4: Why it matters | C4: Kind | D4: Status
A5: LawAI op-ed by Mackenzie Arnold and Stephan Llerena, Guardian, 8 Sep 2026 | B5: Likely essential for the legal section: criticises the narrow METR/Redwood review and proposes an NTSB-style investigator | C5: Could not open (blocked)
A6: Heidy Khlaaf comment in Nature | B6: Expert safety-engineering view on the incident | C6: Could not open (fetch failed)
A7: One Luiza Jarovsky post | B7: Fourth expert newsletter post; page would not load | C7: Could not open
A8: Casey Newton's Platformer post on a kill switch | B8: Paywalled; one other Platformer post is already in | C8: Paywalled
A9: Second Peter Wildeford post | B9: Page would not load | C9: Could not open
A10: AEI, Hoover, Heritage, R Street, Niskanen, FAI | B10: Each checked with one combined search only; "not found" is provisional | C10: Check cut short
A11: CAIS AI Safety Newsletter issues 81 onwards | B11: Later issues may cover the METR report | C11: Check cut short
A12: International AI Safety Report key update | B12: Most authoritative synthesis, if one exists | C12: Check cut short
A13: Helen Toner and Kevin Frazier newsletters | B13: Second searches were refused by the search limit | C13: Check cut short
A14: BlueDot lesson text (FAIG Unit 1.3, AGI Strategy Unit 1.4) | B14: Only reading lists were visible; lesson text needs a login | C14: Needs your login
A16: Yellow cells are for you to fill in, e.g. "Done", "PDF sent" or "Skip".
